Workbook

Sheet Sheet1
A1: Facno | B1: facName | C1: YearEstablished | D1: Method | E1: IsActive | F1: GramaNiladhariDivision | G1: Village | H1: ElevationHeight | I1: GreenTeaAvgQty | J1: FacAddress | K1: capacity | L1: Elvation | M1: subelevation | N1: AdminDistrict | O1: DSDivision | P1: ATCReg | Q1: InspectorRegion | R1: Agrodiv | S1: ManagementType | T1: Location
A2: MF0003 | B2: OLIPHANT | C2: 2021 | D2: OTHER | E2: 0 | F2: 535N Kalapura/Shanthipura | G2: Shanthipura | H2: 6700 | I2: 6500 | J2: Nuwaraeliya | K2: NULL | L2: High | M2: WESTERN-HIGH | N2: NUWARA ELIYA | O2: Nuwara Eliya | P2: NUWARA ELIYA | Q2: KOTHMALE | R2: NUWARA ELIYA | S2: MANAGEMENT COMPANY | T2: =Sheet4!H2 -> View Map
A3: MF0004 | B3: MATTAKELLE | C3: 1914 | D3: OTHER | E3: 1 | F3: Talawakelle | G3: Talawakelle | H3: 4500 | I3: 90000 | J3: Mattakelle Estate, Lindula | K3: 55000 | L3: High | M3: WESTERN-HIGH | N3: NUWARA ELIYA | O3: Nuwara Eliya | P3: NUWARA ELIYA | Q3: THALAWAKELLE | R3: NANUOYA LINDULA TALAWAKELE | S3: MANAGEMENT COMPANY | T3: =Sheet4!H3 -> View Map
A4: MF0005 | B4: STONY CLIFF GROUP | C4: 1925 | D4: OTHER | E4: 1 | F4: Kotagala | G4: Kotagala | H4: 4670 | I4: 64000 | J4: Stony cliff Group, Kotagala, Nuwara Eliya | K4: 64000 | L4: High | M4: WESTERN-HIGH | N4: NUWARA ELIYA | O4: kothmale | P4: NUWARA ELIYA | Q4: KOTHMALE | R4: PATANA KOTAGALA | S4: MANAGEMENT COMPANY | T4: =Sheet4!H4 -> View Map
A5: MF0006 | B5: Nagastenne Refuse Tea Processing | C5: 2020 | D5: OTHER | E5: 1 | F5: Seaporth | H5: 0 | I5: 30000 | J5: Nagastenna Estate, Nawalapitiya | K5: 30000 | L5: Medium | M5: WESTERN-MEDIUM | N5: KANDY | O5: Pasbage Korale | P5: GAMPOLA | Q5: NAWALAPITIYA | R5: GAMPOLA NAWALAPITIYA DOLOSBAGE | S5: SLSPC/JEDB | T5: =Sheet4!H5 -> View Map
A6: MF0007 | B6: GALAMUDUNA | C6: 2014 | D6: OTHER | E6: 1 | F6: Uda Rambukpitiya | G6: Dolosbage | H6: 1068 | I6: 42000 | J6: Galamuduna Estate, Dolosbage | K6: 42000 | L6: Medium | M6: WESTERN-MEDIUM | N6: KANDY | O6: Ganga Ihala Korale | P6: GAMPOLA | Q6: NAWALAPITIYA | R6: GAMPOLA NAWALAPITIYA DOLOSBAGE | S6: MANAGEMENT COMPANY | T6: =Sheet4!H6 -> View Map
A7: MF0008 | B7: Goorookoya | C7: 2020 | D7: OTHER | E7: 1 | F7: Polwathura | G7: Pahala Goorookoya | H7: 610 | I7: 35000 | J7: Pahala Goorookoya,Nawalapitiya. | K7: 35000 | L7: Low | M7: LOW | N7: NUWARA ELIYA | O7: Kotmale | P7: GAMPOLA | Q7: NAWALAPITIYA | R7: GAMPOLA NAWALAPITIYA DOLOSBAGE | S7: PRIVATE | T7: =Sheet4!H7 -> View Map
A8: MF0009 | B8: Enselwatte | C8: 2005 | D8: OTHER | E8: 1 | F8: Kandilpana | H8: 0 | I8: 58000 | J8: Ensalwatta, Deniyaya | K8: 58000 | L8: Low | M8: LOW | N8: MATARA | O8: Kotapola | P8: MATARA | Q8: DENIYAYA | R8: DENIYAYA | S8: MANAGEMENT COMPANY | T8: =Sheet4!H8 -> View Map
A9: MF0010 | B9: KALUGOLLA | C9: 2005 | D9: ORTHODOX | E9: 0 | F9: NULL | G9: Dunukevila | H9: 3000 | I9: 0 | J9: Pussellawa. | K9: NULL | L9: Medium | M9: NULL | N9: KANDY | O9: Uda Palatha | P9: GAMPOLA | Q9: GAMPOLA | R9: PUSSELLAWA HEWAHETA | S9: MANAGEMENT COMPANY | T9: =Sheet4!H9 -> View Map
A10: MF0011 | B10: DIYAGAMA WEST | C10: 1936 | D10: OTHER | E10: 1 | F10: Dayagama West | H10: 0 | I10: 125000 | J10: Deyagama Bazar | K10: 73000 | L10: High | M10: WESTERN-HIGH | N10: NUWARA ELIYA | O10: Nuwara Eliya | P10: NUWARA ELIYA | Q10: THALAWAKELLE | R10: AGARAPATANA | S10: MANAGEMENT COMPANY | T10: =Sheet4!H10 -> View Map
A11: MF0012 | B11: DIYAGAMA EAST | C11: 1927 | D11: OTHER | E11: 1 | F11: Agarapatana | H11: 5500 | I11: 85000 | J11: Dayagama, Nuwara Eliya | K11: 38000 | L11: High | M11: WESTERN-HIGH | N11: NUWARA ELIYA | O11: Nuwara Eliya | P11: NUWARA ELIYA | Q11: THALAWAKELLE | R11: AGARAPATANA | S11: MANAGEMENT COMPANY | T11: =Sheet4!H11 -> View Map
A12: MF0013 | B12: NEW PEACOCK GROUP | C12: 1926 | D12: OTHER | E12: 1 | F12: Doragala | G12: Pussellawa | H12: 884 | I12: 70000 | J12: New Peacock Estate, Pussellawa | K12: 70000 | L12: Medium | M12: WESTERN-MEDIUM | N12: KANDY | O12: Uda Palatha | P12: GAMPOLA | Q12: GAMPOLA | R12: GAMPOLA NAWALAPITIYA DOLOSBAGE | S12: MANAGEMENT COMPANY | T12: =Sheet4!H12 -> View Map
A13: MF0014 | B13: NILAMBA | C13: 1984 | D13: OTHER | E13: 0 | F13: Nillamba | G13: Palledeltota | H13: 1600 | I13: 23920 | J13: Udahewaheta Estate, Galaha | K13: NULL | L13: Medium | M13: WESTERN-MEDIUM | N13: KANDY | O13: Uda Palatha | P13: GAMPOLA | Q13: KANDY | R13: KANDY MATALE KURUNEGALA | S13: PRIVATE | T13: =Sheet4!H13 -> View Map
A14: MF0015 | B14: GREAT VELLEY | C14: 2005 | D14: OTHER | E14: 0 | G14: Karagastenna | H14: 3500 | I14: 0 | J14: Deltota. | K14: NULL | L14: Medium | M14: WESTERN-MEDIUM | N14: KANDY | O14: Pata Hewaheta | P14: GAMPOLA | Q14: KANDY | R14: PUSSELLAWA HEWAHETA | S14: PRIVATE | T14: =Sheet4!H14 -> View Map
A15: MF0016 | B15: Beverley | C15: 2005 | D15: OTHER | E15: 1 | F15: Kandilpana | G15: Kiriwaldola | H15: 660 | I15: 30000 | J15: Deniyaya | K15: 30000 | L15: Low | M15: LOW | N15: MATARA | O15: Pitabeddara | P15: MATARA | Q15: DENIYAYA | R15: DENIYAYA | S15: MANAGEMENT COMPANY | T15: =Sheet4!H15 -> View Map
A16: MF0019 | B16: VELANA | C16: 0 | D16: ORTHODOX | E16: 0 | F16: Vilanagama | G16: Valangama | H16: 1992 | I16: 17748 | J16: Velangama, Akurana | K16: NULL | L16: Medium | M16: WESTERN-MEDIUM | N16: KANDY | O16: Akurana | P16: GAMPOLA | Q16: KANDY | R16: KANDY MATALE KURUNEGALA | S16: PRIVATE | T16: =Sheet4!H16 -> View Map
A17: MF0020 | B17: Kurugama | C17: 2024 | D17: OTHER | E17: 0 | F17: Kurugama | G17: Muruthalawa | H17: 762 | I17: 95000 | J17: Kurugama Estate, MuruthalwaVia Kandy | K17: 95000 | L17: Medium | M17: WESTERN-MEDIUM | N17: KANDY | O17: Yatinuwara | P17: GAMPOLA | Q17: MAWANELLA | R17: KADUGANNAWA | S17: PRIVATE | T17: =Sheet4!H17 -> View Map
A18: MF0021 | B18: GORDON | C18: 0 | D18: OTHER | E18: 1 | F18: Delmar | G18: Udapussellawa | H18: 4600 | I18: 50000 | J18: Udapussellawa | K18: 31000 | L18: High | M18: UVA-HIGH | N18: NUWARA ELIYA | O18: Walapane | P18: NUWARA ELIYA | Q18: WALAPANE | R18: UDAPUSSELLAWA HALGRANOYA | S18: MANAGEMENT COMPANY | T18: =Sheet4!H18 -> View Map
A19: MF0022 | B19: Powysland | C19: 2024 | D19: OTHER | E19: 1 | F19: DAYAGAMA | H19: 5500 | I19: 15000 | J19: Powysland Estate, Dayagama Via, Nuwara Eliya | K19: 15000 | L19: High | M19: WESTERN-HIGH | N19: NUWARA ELIYA | O19: Nuwara Eliya | P19: NUWARA ELIYA | Q19: THALAWAKELLE | R19: AGARAPATANA | S19: PRIVATE | T19: =Sheet4!H19 -> View Map
A20: MF0024 | B20: Bolagala | C20: 2016 | D20: OTHER | E20: 1 | F20: Palkumbura | G20: Palkumbura | H20: 600 | I20: 40000 | J20: Werellagama. | K20: 40000 | L20: Medium | M20: WESTERN-MEDIUM | N20: KANDY | O20: Harispattuwa | P20: GAMPOLA | Q20: KANDY | R20: KADUGANNAWA | S20: PRIVATE | T20: =Sheet4!H20 -> View Map
A21: MF0025 | B21: NEW RATHWATTE | C21: 2014 | D21: OTHER | E21: 0 | F21: Hunuketawala | G21: Ratwatta | H21: 1950 | I21: 50000 | J21: Rathwatte Estate, Udathenna, Matale | K21: NULL | L21: Medium | M21: WESTERN-MEDIUM | N21: MATALE | O21: Ukuwela | P21: GAMPOLA | Q21: MATALE | R21: KANDY MATALE KURUNEGALA | S21: PRIVATE | T21: =Sheet4!H21 -> View Map
A22: MF0029 | B22: HUGOLAND | C22: 2021 | D22: OTHER | E22: 0 | G22: Lunuwatte | H22: 3500 | I22: 0 | J22: Hugoland Estate, Lunuwatte, Welimada | K22: NULL | L22: Medium | M22: UVA-MEDIUM | N22: BADULLA | O22: Uwa Paranagama | P22: BANDARAWELA | Q22: WELIMADA | R22: UDAPUSSELLAWA HALGRANOYA | S22: MANAGEMENT COMPANY | T22: =Sheet4!H22 -> View Map
A23: MF0030 | B23: Noragalla | C23: 0 | D23: OTHER | E23: 1 | F23: POTHTHAKANDE | H23: 500 | I23: 11500 | J23: Noragalla, Nivithigala | K23: 11500 | L23: Low | M23: LOW | N23: RATNAPURA | O23: Pelmadulla | P23: RATNAPURA | Q23: RATNAPURA | R23: RATNAPURA | S23: MANAGEMENT COMPANY | T23: =Sheet4!H23 -> View Map
A24: MF0032 | B24: BROWNLOW | C24: 2021 | D24: OTHER | E24: 0 | G24: Maskeliya | H24: 1200 | I24: 90000 | J24: Brownlow Estate ,Maskeliya | K24: NULL | L24: High | M24: WESTERN-HIGH | N24: NUWARA ELIYA | O24: Ambagamuwa | P24: NUWARA ELIYA | Q24: GINIGATHHENA | R24: UPCOT MASKELIYAB8 | S24: MANAGEMENT COMPANY | T24: =Sheet4!H24 -> View Map
A25: MF0033 | B25: TROUP | C25: 0 | D25: OTHER | E25: 1 | F25: TROUP -475/A | H25: 1379 | I25: 30000 | J25: Troup Estate, Talawakelle | K25: 30000 | L25: High | M25: WESTERN-HIGH | N25: NUWARA ELIYA | O25: Nuwara Eliya | P25: NUWARA ELIYA | Q25: THALAWAKELLE | R25: NANUOYA LINDULA TALAWAKELE | S25: MANAGEMENT COMPANY | T25: =Sheet4!H25 -> View Map
A26: MF0034 | B26: STRATHSPEY | C26: 2005 | D26: OTHER | E26: 1 | F26: UPCOT | H26: 1350 | I26: 65000 | J26: Strathspey Estate, Upcot | K26: 65000 | L26: High | M26: WESTERN-HIGH | N26: NUWARA ELIYA | O26: Ambagamuwa | P26: NUWARA ELIYA | Q26: Norwood | R26: UPCOT MASKELIYAB8 | S26: MANAGEMENT COMPANY | T26: =Sheet4!H26 -> View Map
A27: MF0037 | B27: GOWERAKELLE | C27: 2005 | D27: OTHER | E27: 0 | H27: 0 | I27: 0 | K27: NULL | L27: High | M27: UVA-HIGH | N27: BADULLA | O27: Hali-Ela | P27: GAMPOLA | Q27: HALI-ELLA | R27: DEMODARA HALIELLA BADULLA | S27: PRIVATE | T27: =Sheet4!H27 -> View Map
A28: MF0039 | B28: OHIYA | C28: 2005 | D28: OTHER | E28: 0 | H28: 0 | I28: 0 | J28: Railway Station, Ohiya | K28: NULL | L28: High | M28: UVA-HIGH | N28: BADULLA | O28: NULL | P28: BANDARAWELA | Q28: NULL | R28: HAPUTALE | S28: MANAGEMENT COMPANY | T28: =Sheet4!H28 -> View Map
A29: MF0041 | B29: Debedde | C29: 2005 | D29: OTHER | E29: 1 | F29: Pelagahatenna | G29: Pelgahatenna | H29: 3648 | I29: 40000 | J29: Ury EstatePassara | K29: 40000 | L29: Medium | M29: UVA-MEDIUM | N29: BADULLA | O29: Passara | P29: BANDARAWELA | Q29: PASSARA | R29: PASSARA LUNUGALLA | S29: MANAGEMENT COMPANY | T29: =Sheet4!H29 -> View Map
A30: MF0042 | B30: HANTANE | C30: 2005 | D30: OTHER | E30: 0 | H30: 0 | I30: 0 | K30: NULL | L30: Medium | M30: WESTERN-MEDIUM | N30: KANDY | O30: Ganga wata Korale | P30: GAMPOLA | Q30: KANDY | R30: NILAMBE HANTANE GALAHA | S30: SLSPC/JEDB | T30: =Sheet4!H30 -> View Map
A31: MF0043 | B31: ST. CLAIR | C31: 0 | D31: OTHER | E31: 1 | F31: Devon | G31: Ulapane | H31: 476 | I31: 28000 | J31: St. Clair EstateThalawakelle. | K31: 28000 | L31: High | M31: WESTERN-HIGH | N31: NUWARA ELIYA | O31: Nuwara Eliya | P31: NUWARA ELIYA | Q31: THALAWAKELLE | R31: NANUOYA LINDULA TALAWAKELE | S31: MANAGEMENT COMPANY | T31: =Sheet4!H31 -> View Map
A32: MF0044 | B32: MAHANILU | C32: 2014 | D32: OTHER | E32: 1 | F32: Mahanilu (320K) | H32: 4224 | I32: 25000 | J32: Mahanilu EstateUpcot | K32: 25000 | L32: High | M32: WESTERN-HIGH | N32: NUWARA ELIYA | O32: Ambagamuwa | P32: NUWARA ELIYA | Q32: Norwood | R32: UPCOT MASKELIYAB8 | S32: MANAGEMENT COMPANY | T32: =Sheet4!H32 -> View Map
A33: MF0048 | B33: Needwood | C33: 2024 | D33: OTHER | E33: 1 | F33: Haldamulla | G33: Needwood Estate | H33: 1450 | I33: 15000 | J33: Needwood Estate,Haldummulla,Badulla. | K33: 15000 | L33: High | M33: UVA-HIGH | N33: BADULLA | O33: Haldummulla | P33: BANDARAWELA | Q33: BANDARAWELA | R33: KOSLANDA HALDUMULLA | S33: PRIVATE | T33: =Sheet4!H33 -> View Map
A34: MF0049 | B34: Iddalgashinna | C34: 1940 | D34: OTHER | E34: 1 | F34: Beragala | G34: Idalgashinna | H34: 5000 | I34: 18000 | J34: IddalgashinnaBandarawela | K34: 18000 | L34: High | M34: UVA-HIGH | N34: BADULLA | O34: Haldummulla | P34: BANDARAWELA | Q34: BANDARAWELA | R34: HAPUTALE | S34: PRIVATE | T34: =Sheet4!H34 -> View Map
A35: MF0056 | B35: HELLBODDE | C35: 1953 | D35: OTHER | E35: 1 | F35: Katulithula | G35: Helbodde | H35: 4900 | I35: 64000 | J35: Hellbodde EstateKatukitula | K35: 64000 | L35: High | M35: WESTERN-HIGH | N35: NUWARA ELIYA | O35: kothmale | P35: NUWARA ELIYA | Q35: KOTHMALE | R35: PUSSELLAWA HEWAHETA | S35: MANAGEMENT COMPANY | T35: =Sheet4!H35 -> View Map
A36: MF0061 | B36: Handford | C36: 2005 | D36: OTHER | E36: 1 | F36: Kalugalahena | G36: Deniyaya | H36: 1500 | I36: 26000 | J36: Handford EstateDeniyaya | K36: NULL | L36: Low | M36: LOW | N36: MATARA | O36: Kotapola | P36: MATARA | Q36: DENIYAYA | R36: DENIYAYA | S36: MANAGEMENT COMPANY | T36: =Sheet4!H36 -> View Map
A37: MF0062 | B37: Kelaneiya Estates | C37: 1939 | D37: OTHER | E37: 1 | F37: 320/N,BROWNLOW | G37: Maskeliya | H37: 4364 | I37: 15000 | J37: Kelaneiya EstateMaskeliya | K37: 15000 | L37: High | M37: WESTERN-HIGH | N37: NUWARA ELIYA | O37: Ambagamuwa | P37: NUWARA ELIYA | Q37: GINIGATHHENA | R37: UPCOT MASKELIYAB8 | S37: PRIVATE | T37: =Sheet4!H37 -> View Map
A38: MF0064 | B38: Anninkande | C38: 0 | D38: OTHER | E38: 1 | F38: KALUGAHAHENA | G38: Viharahena | H38: 1738 | I38: 25000 | J38: Aninkanda EstateDeniyaya | K38: 25000 | L38: Low | M38: LOW | N38: MATARA | O38: Kotapola | P38: MATARA | Q38: DENIYAYA | R38: DENIYAYA | S38: MANAGEMENT COMPANY | T38: =Sheet4!H38 -> View Map
A39: MF0066 | B39: GOURAVILLA | C39: 1928 | D39: OTHER | E39: 1 | F39: Gauravilla | H39: 0 | I39: 46000 | J39: Gouravilla EstateUpcotMaskeliya | K39: 46000 | L39: High | M39: WESTERN-HIGH | N39: NUWARA ELIYA | O39: Ambagamuwa | P39: NUWARA ELIYA | Q39: Norwood | R39: UPCOT MASKELIYAB8 | S39: MANAGEMENT COMPANY | T39: =Sheet4!H39 -> View Map
A40: MF0067 | B40: LIDDESDALE | C40: 2005 | D40: OTHER | E40: 1 | F40: Rathnayakapura | H40: 5200 | I40: 60000 | J40: Liddesdale GroupThe Standard Tea Co Of Ceylon Ltd,Clomessrs George Steuart and Co Ltd,PO Box 151,Colombo. | K40: 60000 | L40: High | M40: UVA-HIGH | N40: NUWARA ELIYA | O40: Walapane | P40: NUWARA ELIYA | Q40: WALAPANE | R40: UDAPUSSELLAWA HALGRANOYA | S40: MANAGEMENT COMPANY | T40: =Sheet4!H40 -> View Map
...

Sheet Sheet4
A1: FacNo | B1: Factory Name | C1: Distrct | D1: DS | E1: GS | F1: Village | G1: Address | H1: URL | I1: Lant | J1: Long
B2: =PROPER(Sheet1!$B2&" "&"Tea Factory") -> Oliphant Tea Factory | F2: =Sheet1!G2 -> Shanthipura | G2: =Sheet1!J2 -> Nuwaraeliya | H2: =HYPERLINK("https://www.google.com/maps/search/"&SUBSTITUTE($B2,"","+")," View Map ") -> View Map
B3: =PROPER(Sheet1!$B3&" "&"Tea Factory") -> Mattakelle Tea Factory | F3: =Sheet1!G3 -> Talawakelle | G3: =Sheet1!J3 -> Mattakelle Estate, Lindula | H3: =HYPERLINK("https://www.google.com/maps/search/"&SUBSTITUTE($B3,"","+")," View Map ") -> View Map
B4: =PROPER(Sheet1!$B4&" "&"Tea Factory") -> Stony Cliff Group Tea Factory | F4: =Sheet1!G4 -> Kotagala | G4: =Sheet1!J4 -> Stony cliff Group, Kotagala, Nuwara Eliya | H4: =HYPERLINK("https://www.google.com/maps/search/"&SUBSTITUTE($B4,"","+")," View Map ") -> View Map
B5: =PROPER(Sheet1!$B5&" "&"Tea Factory") -> Nagastenne Refuse Tea Processing Tea Factory | F5: =Sheet1!G5 -> 0 | G5: =Sheet1!J5 -> Nagastenna Estate, Nawalapitiya | H5: =HYPERLINK("https://www.google.com/maps/search/"&SUBSTITUTE($B5,"","+")," View Map ") -> View Map
B6: =PROPER(Sheet1!$B6&" "&"Tea Factory") -> Galamuduna Tea Factory | F6: =Sheet1!G6 -> Dolosbage | G6: =Sheet1!J6 -> Galamuduna Estate, Dolosbage | H6: =HYPERLINK("https://www.google.com/maps/search/"&SUBSTITUTE($B6,"","+")," View Map ") -> View Map
B7: =PROPER(Sheet1!$B7&" "&"Tea Factory") -> Goorookoya Tea Factory | F7: =Sheet1!G7 -> Pahala Goorookoya | G7: =Sheet1!J7 -> Pahala Goorookoya,Nawalapitiya. | H7: =HYPERLINK("https://www.google.com/maps/search/"&SUBSTITUTE($B7,"","+")," View Map ") -> View Map
B8: =PROPER(Sheet1!$B8&" "&"Tea Factory") -> Enselwatte Tea Factory | F8: =Sheet1!G8 -> 0 | G8: =Sheet1!J8 -> Ensalwatta, Deniyaya | H8: =HYPERLINK("https://www.google.com/maps/search/"&SUBSTITUTE($B8,"","+")," View Map ") -> View Map
B9: =PROPER(Sheet1!$B9&" "&"Tea Factory") -> Kalugolla Tea Factory | F9: =Sheet1!G9 -> Dunukevila | G9: =Sheet1!J9 -> Pussellawa. | H9: =HYPERLINK("https://www.google.com/maps/search/"&SUBSTITUTE($B9,"","+")," View Map ") -> View Map
B10: =PROPER(Sheet1!$B10&" "&"Tea Factory") -> Diyagama West Tea Factory | F10: =Sheet1!G10 -> 0 | G10: =Sheet1!J10 -> Deyagama Bazar | H10: =HYPERLINK("https://www.google.com/maps/search/"&SUBSTITUTE($B10,"","+")," View Map ") -> View Map
B11: =PROPER(Sheet1!$B11&" "&"Tea Factory") -> Diyagama East Tea Factory | F11: =Sheet1!G11 -> 0 | G11: =Sheet1!J11 -> Dayagama, Nuwara Eliya | H11: =HYPERLINK("https://www.google.com/maps/search/"&SUBSTITUTE($B11,"","+")," View Map ") -> View Map
B12: =PROPER(Sheet1!$B12&" "&"Tea Factory") -> New Peacock Group Tea Factory | F12: =Sheet1!G12 -> Pussellawa | G12: =Sheet1!J12 -> New Peacock Estate, Pussellawa | H12: =HYPERLINK("https://www.google.com/maps/search/"&SUBSTITUTE($B12,"","+")," View Map ") -> View Map
B13: =PROPER(Sheet1!$B13&" "&"Tea Factory") -> Nilamba Tea Factory | F13: =Sheet1!G13 -> Palledeltota | G13: =Sheet1!J13 -> Udahewaheta Estate, Galaha | H13: =HYPERLINK("https://www.google.com/maps/search/"&SUBSTITUTE($B13,"","+")," View Map ") -> View Map
... B1056: =PROPER(Sheet1!$B1056&" "&"Tea Factory") -> Maleesha Tea Factory | F1056: =Sheet1!G1056 -> 0 | G1056: =Sheet1!J1056 -> Omaththa,Agalawaththa. | H1056: =HYPERLINK("https://www.google.com/maps/search/"&SUBSTITUTE($B1056,"","+")," View Map ") -> View Map
